2024-03-07 17:06:15,406 INFO    StreamThr :29928 [internal.py:wandb_internal():86] W&B internal server running at pid: 29928, started at: 2024-03-07 17:06:15.406817
2024-03-07 17:06:15,406 DEBUG   HandlerThread:29928 [handler.py:handle_request():146] handle_request: status
2024-03-07 17:06:15,422 INFO    WriterThread:29928 [datastore.py:open_for_write():87] open: C:\Users\sebja\Dropbox\github\offset-credits-rl\multi-agent\wandb\run-20240307_170615-tgezkufd\run-tgezkufd.wandb
2024-03-07 17:06:15,422 DEBUG   SenderThread:29928 [sender.py:send():382] send: header
2024-03-07 17:06:15,485 DEBUG   SenderThread:29928 [sender.py:send():382] send: run
2024-03-07 17:06:15,612 ERROR   SenderThread:29928 [internal_api.py:execute():373] 404 response executing GraphQL.
2024-03-07 17:06:15,612 ERROR   SenderThread:29928 [internal_api.py:execute():374] {"errors":[{"message":"project not found","path":["upsertBucket"]}],"data":{"upsertBucket":null}}
2024-03-07 17:06:15,628 ERROR   SenderThread:29928 [sender.py:send_run():987] It appears that you do not have permission to access the requested resource. Please reach out to the project owner to grant you access. If you have the correct permissions, verify that there are no issues with your networking setup.(Error 404: Not Found)
Traceback (most recent call last):
  File "C:\Users\sebja\anaconda3\lib\site-packages\wandb\sdk\lib\retry.py", line 131, in __call__
    result = self._call_fn(*args, **kwargs)
  File "C:\Users\sebja\anaconda3\lib\site-packages\wandb\sdk\internal\internal_api.py", line 369, in execute
    return self.client.execute(*args, **kwargs)  # type: ignore
  File "C:\Users\sebja\anaconda3\lib\site-packages\wandb\vendor\gql-0.2.0\wandb_gql\client.py", line 52, in execute
    result = self._get_result(document, *args, **kwargs)
  File "C:\Users\sebja\anaconda3\lib\site-packages\wandb\vendor\gql-0.2.0\wandb_gql\client.py", line 60, in _get_result
    return self.transport.execute(document, *args, **kwargs)
  File "C:\Users\sebja\anaconda3\lib\site-packages\wandb\sdk\lib\gql_request.py", line 59, in execute
    request.raise_for_status()
  File "C:\Users\sebja\anaconda3\lib\site-packages\requests\models.py", line 1021, in raise_for_status
    raise HTTPError(http_error_msg, response=self)
requests.exceptions.HTTPError: 404 Client Error: Not Found for url: https://api.wandb.ai/graphql

During handling of the above exception, another exception occurred:

Traceback (most recent call last):
  File "C:\Users\sebja\anaconda3\lib\site-packages\wandb\sdk\internal\sender.py", line 985, in send_run
    self._init_run(run, config_value_dict)
  File "C:\Users\sebja\anaconda3\lib\site-packages\wandb\sdk\internal\sender.py", line 1027, in _init_run
    server_run, inserted, server_messages = self._api.upsert_run(
  File "C:\Users\sebja\anaconda3\lib\site-packages\wandb\apis\normalize.py", line 73, in wrapper
    raise err
  File "C:\Users\sebja\anaconda3\lib\site-packages\wandb\apis\normalize.py", line 41, in wrapper
    return func(*args, **kwargs)
  File "C:\Users\sebja\anaconda3\lib\site-packages\wandb\sdk\internal\internal_api.py", line 2216, in upsert_run
    response = self.gql(
  File "C:\Users\sebja\anaconda3\lib\site-packages\wandb\sdk\internal\internal_api.py", line 341, in gql
    ret = self._retry_gql(
  File "C:\Users\sebja\anaconda3\lib\site-packages\wandb\sdk\lib\retry.py", line 147, in __call__
    retry_timedelta_triggered = check_retry_fn(e)
  File "C:\Users\sebja\anaconda3\lib\site-packages\wandb\util.py", line 965, in check_retry_fn
    return fallback_retry_fn(e)
  File "C:\Users\sebja\anaconda3\lib\site-packages\wandb\util.py", line 907, in no_retry_auth
    raise CommError(
wandb.errors.CommError: It appears that you do not have permission to access the requested resource. Please reach out to the project owner to grant you access. If you have the correct permissions, verify that there are no issues with your networking setup.(Error 404: Not Found)
2024-03-07 17:06:20,694 DEBUG   HandlerThread:29928 [handler.py:handle_request():146] handle_request: status_report
2024-03-07 17:06:25,748 DEBUG   HandlerThread:29928 [handler.py:handle_request():146] handle_request: status_report
2024-03-07 17:06:30,779 DEBUG   HandlerThread:29928 [handler.py:handle_request():146] handle_request: status_report
2024-03-07 17:06:35,805 DEBUG   HandlerThread:29928 [handler.py:handle_request():146] handle_request: status_report
2024-03-07 17:06:40,830 DEBUG   HandlerThread:29928 [handler.py:handle_request():146] handle_request: status_report
2024-03-07 17:06:45,880 DEBUG   HandlerThread:29928 [handler.py:handle_request():146] handle_request: status_report
2024-03-07 17:06:50,912 DEBUG   HandlerThread:29928 [handler.py:handle_request():146] handle_request: status_report
2024-03-07 17:06:55,949 DEBUG   HandlerThread:29928 [handler.py:handle_request():146] handle_request: status_report
2024-03-07 17:07:00,979 DEBUG   HandlerThread:29928 [handler.py:handle_request():146] handle_request: status_report
2024-03-07 17:07:06,015 DEBUG   HandlerThread:29928 [handler.py:handle_request():146] handle_request: status_report
2024-03-07 17:07:11,067 DEBUG   HandlerThread:29928 [handler.py:handle_request():146] handle_request: status_report
2024-03-07 17:07:16,099 DEBUG   HandlerThread:29928 [handler.py:handle_request():146] handle_request: status_report
2024-03-07 17:07:21,131 DEBUG   HandlerThread:29928 [handler.py:handle_request():146] handle_request: status_report
2024-03-07 17:07:26,164 DEBUG   HandlerThread:29928 [handler.py:handle_request():146] handle_request: status_report
2024-03-07 17:07:31,200 DEBUG   HandlerThread:29928 [handler.py:handle_request():146] handle_request: status_report
2024-03-07 17:07:36,233 DEBUG   HandlerThread:29928 [handler.py:handle_request():146] handle_request: status_report
2024-03-07 17:07:41,252 DEBUG   HandlerThread:29928 [handler.py:handle_request():146] handle_request: status_report
2024-03-07 17:07:46,279 DEBUG   HandlerThread:29928 [handler.py:handle_request():146] handle_request: status_report
2024-03-07 17:07:51,315 DEBUG   HandlerThread:29928 [handler.py:handle_request():146] handle_request: status_report
2024-03-07 17:07:56,359 DEBUG   HandlerThread:29928 [handler.py:handle_request():146] handle_request: status_report
2024-03-07 17:08:01,404 DEBUG   HandlerThread:29928 [handler.py:handle_request():146] handle_request: status_report
2024-03-07 17:08:06,441 DEBUG   HandlerThread:29928 [handler.py:handle_request():146] handle_request: status_report
2024-03-07 17:08:11,494 DEBUG   HandlerThread:29928 [handler.py:handle_request():146] handle_request: status_report
2024-03-07 17:08:16,541 DEBUG   HandlerThread:29928 [handler.py:handle_request():146] handle_request: status_report
2024-03-07 17:08:21,593 DEBUG   HandlerThread:29928 [handler.py:handle_request():146] handle_request: status_report
2024-03-07 17:08:26,628 DEBUG   HandlerThread:29928 [handler.py:handle_request():146] handle_request: status_report
2024-03-07 17:08:31,653 DEBUG   HandlerThread:29928 [handler.py:handle_request():146] handle_request: status_report
2024-03-07 17:08:36,699 DEBUG   HandlerThread:29928 [handler.py:handle_request():146] handle_request: status_report
2024-03-07 17:08:41,406 INFO    StreamThr :29928 [internal.py:wandb_internal():86] W&B internal server running at pid: 29928, started at: 2024-03-07 17:08:41.405719
2024-03-07 17:08:41,408 DEBUG   HandlerThread:29928 [handler.py:handle_request():146] handle_request: status
2024-03-07 17:08:41,422 INFO    WriterThread:29928 [datastore.py:open_for_write():87] open: C:\Users\sebja\Dropbox\github\offset-credits-rl\multi-agent\wandb\run-20240307_170841-o56790au\run-o56790au.wandb
2024-03-07 17:08:41,423 DEBUG   SenderThread:29928 [sender.py:send():382] send: header
2024-03-07 17:08:41,477 DEBUG   SenderThread:29928 [sender.py:send():382] send: run
2024-03-07 17:08:41,608 ERROR   SenderThread:29928 [internal_api.py:execute():373] 403 response executing GraphQL.
2024-03-07 17:08:41,608 ERROR   SenderThread:29928 [internal_api.py:execute():374] {"errors":[{"message":"permission denied","path":["upsertBucket"],"extensions":{"code":"PERMISSION_ERROR"}}],"data":{"upsertBucket":null}}
2024-03-07 17:08:41,609 ERROR   SenderThread:29928 [sender.py:send_run():987] It appears that you do not have permission to access the requested resource. Please reach out to the project owner to grant you access. If you have the correct permissions, verify that there are no issues with your networking setup.(Error 403: Forbidden)
Traceback (most recent call last):
  File "C:\Users\sebja\anaconda3\lib\site-packages\wandb\sdk\lib\retry.py", line 131, in __call__
    result = self._call_fn(*args, **kwargs)
  File "C:\Users\sebja\anaconda3\lib\site-packages\wandb\sdk\internal\internal_api.py", line 369, in execute
    return self.client.execute(*args, **kwargs)  # type: ignore
  File "C:\Users\sebja\anaconda3\lib\site-packages\wandb\vendor\gql-0.2.0\wandb_gql\client.py", line 52, in execute
    result = self._get_result(document, *args, **kwargs)
  File "C:\Users\sebja\anaconda3\lib\site-packages\wandb\vendor\gql-0.2.0\wandb_gql\client.py", line 60, in _get_result
    return self.transport.execute(document, *args, **kwargs)
  File "C:\Users\sebja\anaconda3\lib\site-packages\wandb\sdk\lib\gql_request.py", line 59, in execute
    request.raise_for_status()
  File "C:\Users\sebja\anaconda3\lib\site-packages\requests\models.py", line 1021, in raise_for_status
    raise HTTPError(http_error_msg, response=self)
requests.exceptions.HTTPError: 403 Client Error: Forbidden for url: https://api.wandb.ai/graphql

During handling of the above exception, another exception occurred:

Traceback (most recent call last):
  File "C:\Users\sebja\anaconda3\lib\site-packages\wandb\sdk\internal\sender.py", line 985, in send_run
    self._init_run(run, config_value_dict)
  File "C:\Users\sebja\anaconda3\lib\site-packages\wandb\sdk\internal\sender.py", line 1027, in _init_run
    server_run, inserted, server_messages = self._api.upsert_run(
  File "C:\Users\sebja\anaconda3\lib\site-packages\wandb\apis\normalize.py", line 73, in wrapper
    raise err
  File "C:\Users\sebja\anaconda3\lib\site-packages\wandb\apis\normalize.py", line 41, in wrapper
    return func(*args, **kwargs)
  File "C:\Users\sebja\anaconda3\lib\site-packages\wandb\sdk\internal\internal_api.py", line 2216, in upsert_run
    response = self.gql(
  File "C:\Users\sebja\anaconda3\lib\site-packages\wandb\sdk\internal\internal_api.py", line 341, in gql
    ret = self._retry_gql(
  File "C:\Users\sebja\anaconda3\lib\site-packages\wandb\sdk\lib\retry.py", line 147, in __call__
    retry_timedelta_triggered = check_retry_fn(e)
  File "C:\Users\sebja\anaconda3\lib\site-packages\wandb\util.py", line 965, in check_retry_fn
    return fallback_retry_fn(e)
  File "C:\Users\sebja\anaconda3\lib\site-packages\wandb\util.py", line 907, in no_retry_auth
    raise CommError(
wandb.errors.CommError: It appears that you do not have permission to access the requested resource. Please reach out to the project owner to grant you access. If you have the correct permissions, verify that there are no issues with your networking setup.(Error 403: Forbidden)
2024-03-07 17:08:41,744 DEBUG   HandlerThread:29928 [handler.py:handle_request():146] handle_request: status_report
2024-03-07 17:08:46,541 DEBUG   HandlerThread:29928 [handler.py:handle_request():146] handle_request: keepalive
2024-03-07 17:08:46,662 DEBUG   HandlerThread:29928 [handler.py:handle_request():146] handle_request: status_report
2024-03-07 17:08:46,802 DEBUG   HandlerThread:29928 [handler.py:handle_request():146] handle_request: status_report
2024-03-07 17:08:51,721 DEBUG   HandlerThread:29928 [handler.py:handle_request():146] handle_request: status_report
2024-03-07 17:08:51,841 DEBUG   HandlerThread:29928 [handler.py:handle_request():146] handle_request: status_report
