2024-03-07 17:09:03,978 INFO    StreamThr :14312 [internal.py:wandb_internal():86] W&B internal server running at pid: 14312, started at: 2024-03-07 17:09:03.978428
2024-03-07 17:09:03,978 DEBUG   HandlerThread:14312 [handler.py:handle_request():146] handle_request: status
2024-03-07 17:09:03,994 INFO    WriterThread:14312 [datastore.py:open_for_write():87] open: C:\Users\sebja\Dropbox\github\offset-credits-rl\multi-agent\wandb\run-20240307_170903-w8m7ew1m\run-w8m7ew1m.wandb
2024-03-07 17:09:03,994 DEBUG   SenderThread:14312 [sender.py:send():382] send: header
2024-03-07 17:09:04,044 DEBUG   SenderThread:14312 [sender.py:send():382] send: run
2024-03-07 17:09:04,223 ERROR   SenderThread:14312 [internal_api.py:execute():373] 403 response executing GraphQL.
2024-03-07 17:09:04,223 ERROR   SenderThread:14312 [internal_api.py:execute():374] {"errors":[{"message":"permission denied","path":["upsertBucket"],"extensions":{"code":"PERMISSION_ERROR"}}],"data":{"upsertBucket":null}}
2024-03-07 17:09:04,236 ERROR   SenderThread:14312 [sender.py:send_run():987] It appears that you do not have permission to access the requested resource. Please reach out to the project owner to grant you access. If you have the correct permissions, verify that there are no issues with your networking setup.(Error 403: Forbidden)
Traceback (most recent call last):
  File "C:\Users\sebja\anaconda3\lib\site-packages\wandb\sdk\lib\retry.py", line 131, in __call__
    result = self._call_fn(*args, **kwargs)
  File "C:\Users\sebja\anaconda3\lib\site-packages\wandb\sdk\internal\internal_api.py", line 369, in execute
    return self.client.execute(*args, **kwargs)  # type: ignore
  File "C:\Users\sebja\anaconda3\lib\site-packages\wandb\vendor\gql-0.2.0\wandb_gql\client.py", line 52, in execute
    result = self._get_result(document, *args, **kwargs)
  File "C:\Users\sebja\anaconda3\lib\site-packages\wandb\vendor\gql-0.2.0\wandb_gql\client.py", line 60, in _get_result
    return self.transport.execute(document, *args, **kwargs)
  File "C:\Users\sebja\anaconda3\lib\site-packages\wandb\sdk\lib\gql_request.py", line 59, in execute
    request.raise_for_status()
  File "C:\Users\sebja\anaconda3\lib\site-packages\requests\models.py", line 1021, in raise_for_status
    raise HTTPError(http_error_msg, response=self)
requests.exceptions.HTTPError: 403 Client Error: Forbidden for url: https://api.wandb.ai/graphql

During handling of the above exception, another exception occurred:

Traceback (most recent call last):
  File "C:\Users\sebja\anaconda3\lib\site-packages\wandb\sdk\internal\sender.py", line 985, in send_run
    self._init_run(run, config_value_dict)
  File "C:\Users\sebja\anaconda3\lib\site-packages\wandb\sdk\internal\sender.py", line 1027, in _init_run
    server_run, inserted, server_messages = self._api.upsert_run(
  File "C:\Users\sebja\anaconda3\lib\site-packages\wandb\apis\normalize.py", line 73, in wrapper
    raise err
  File "C:\Users\sebja\anaconda3\lib\site-packages\wandb\apis\normalize.py", line 41, in wrapper
    return func(*args, **kwargs)
  File "C:\Users\sebja\anaconda3\lib\site-packages\wandb\sdk\internal\internal_api.py", line 2216, in upsert_run
    response = self.gql(
  File "C:\Users\sebja\anaconda3\lib\site-packages\wandb\sdk\internal\internal_api.py", line 341, in gql
    ret = self._retry_gql(
  File "C:\Users\sebja\anaconda3\lib\site-packages\wandb\sdk\lib\retry.py", line 147, in __call__
    retry_timedelta_triggered = check_retry_fn(e)
  File "C:\Users\sebja\anaconda3\lib\site-packages\wandb\util.py", line 965, in check_retry_fn
    return fallback_retry_fn(e)
  File "C:\Users\sebja\anaconda3\lib\site-packages\wandb\util.py", line 907, in no_retry_auth
    raise CommError(
wandb.errors.CommError: It appears that you do not have permission to access the requested resource. Please reach out to the project owner to grant you access. If you have the correct permissions, verify that there are no issues with your networking setup.(Error 403: Forbidden)
2024-03-07 17:09:09,312 DEBUG   HandlerThread:14312 [handler.py:handle_request():146] handle_request: status_report
2024-03-07 17:09:14,351 DEBUG   HandlerThread:14312 [handler.py:handle_request():146] handle_request: status_report
2024-03-07 17:09:19,373 DEBUG   HandlerThread:14312 [handler.py:handle_request():146] handle_request: status_report
2024-03-07 17:09:24,406 DEBUG   HandlerThread:14312 [handler.py:handle_request():146] handle_request: status_report
2024-03-07 17:09:29,450 DEBUG   HandlerThread:14312 [handler.py:handle_request():146] handle_request: status_report
2024-03-07 17:09:34,489 DEBUG   HandlerThread:14312 [handler.py:handle_request():146] handle_request: status_report
2024-03-07 17:09:38,256 INFO    StreamThr :14312 [internal.py:wandb_internal():86] W&B internal server running at pid: 14312, started at: 2024-03-07 17:09:38.256247
2024-03-07 17:09:38,272 DEBUG   HandlerThread:14312 [handler.py:handle_request():146] handle_request: status
2024-03-07 17:09:38,273 INFO    WriterThread:14312 [datastore.py:open_for_write():87] open: C:\Users\sebja\Dropbox\github\offset-credits-rl\multi-agent\wandb\run-20240307_170938-ia792nal\run-ia792nal.wandb
2024-03-07 17:09:38,273 DEBUG   SenderThread:14312 [sender.py:send():382] send: header
2024-03-07 17:09:38,319 DEBUG   SenderThread:14312 [sender.py:send():382] send: run
2024-03-07 17:09:38,535 INFO    SenderThread:14312 [dir_watcher.py:__init__():211] watching files in: C:\Users\sebja\Dropbox\github\offset-credits-rl\multi-agent\wandb\run-20240307_170938-ia792nal\files
2024-03-07 17:09:38,535 INFO    SenderThread:14312 [sender.py:_start_run_threads():1136] run started: ia792nal with start time 1709849378.256246
2024-03-07 17:09:39,517 DEBUG   HandlerThread:14312 [handler.py:handle_request():146] handle_request: status_report
